Workbook

Sheet README
A1: The Remnant of Promise Official Study Bible — Projection Model
A2: Prepared for: [father-in-law name] — business advisory review
A3: As-of date: May 23, 2026
A5: Purpose
A6: Three-scenario projection (Conservative / Base / Aspirational) of paying-partner growth, monthly recurring revenue (MRR), and annual recurring revenue (ARR) at 3-month, 6-month, and 12-month horizons for The Remnant of Promise Official Study Bible — the restored-names study Bible app currently in mid-development at bible.remnantofpromise.org. Also captures the feature-parity timeline against Logos Bible Software (the dominant Bible-study suite) and where this app reaches a comparable feature footprint at roughly half Logos's price.
A10: How to use this workbook
A11: 1. The 'Assumptions' tab carries every input as a BLUE cell. Edit any blue cell to update the projections — every other tab recalculates from the assumptions automatically.
A12: 2. The 'Projection' tab carries month-by-month rollups for all three scenarios across the next 12 months (June 2026 through May 2027).
A13: 3. The 'Logos Comparison' tab maps our tier ladder against Logos's three subscription tiers (Premium / Pro / Max) and shows the feature-parity scorecard.
A14: 4. The 'Milestones' tab summarizes the three projection horizons + the feature-parity date + key unit economics (CAC, LTV, LTV/CAC ratio).
A16: Color legend (industry-standard financial-model convention)
A17: Blue text | B17: Hardcoded inputs. Edit these to change the model.
A18: Black text | B18: Formulas. Do not overwrite — they recalculate from inputs.
A19: Green text | B19: Cross-sheet references (pulled from Assumptions tab).
A20: Yellow fill | B20: Key assumption that should be reviewed / replaced with real data.
A22: Important caveats
A23: • The starting state (13 partners, ~$5/mo blended ARPU) is approximate — the founder-pricing cohort blends across tiers and the exact MRR can be confirmed in Stripe. The trajectory math does not depend heavily on the precise starting number.
A24: • Conversion rates and churn rates are industry-typical assumptions for low-price recurring subscription products in niche faith content. Real data after a few months of meaningful acquisition will replace these inputs.
A25: • Logos's subscriber counts and revenue are estimates (Faithlife is privately held). The $26.2M annual revenue figure and 750k+ active monthly user count are from publicly available third-party estimates and the Google Play listing respectively.
A26: • Projections are HYPOTHESES, not forecasts. The model is built to make assumptions explicit and stress-testable, not to predict the future. The honest framing: 'here is what would have to be true for each scenario to land.'

Sheet Assumptions
A1: ASSUMPTIONS — edit BLUE cells to change projections
A3: STARTING STATE (as of model date)
A4: As-of date | B4: 5/23/2026
A5: Paying partners today (total across all paid tiers) | B5: 13 | C5: Midpoint of 1–25 range Yoshi confirmed; replace with exact Stripe count
A6: Blended monthly price per paying partner ($/mo) | B6: 5 | C6: Founder-cohort 50%-off variant pulls blended ARPU below sticker prices
A7: Starting MRR | B7: =B5*B6 -> 65
A8: Starting ARR | B8: =B7*12 -> 780
A10: TIER MIX AT NEW PAID CONVERSION (% of new paid partners)
A11: $1.99 Notes tier | B11: 0.3
A12: $4.99 Library tier | B12: 0.55
A13: $9.99 Power tier (Deeper Dive + chronological + Yoshi's keys) | B13: 0.15
A14: Sum check (must equal 100%) | B14: =B11+B12+B13 -> 1
A15: Blended price of new paid partner ($/mo) | B15: =B11*1.99+B12*4.99+B13*9.99 -> 4.84
A17: TIER PRICING REFERENCE (per DESIGN_LANGUAGE.md §9)
A18: Free tier | B18: $0/mo | C18: Restored sacred names + canon + apocrypha + pseudepigrapha + Strong's + 2 framework cross-ref threads
A19: Notes tier | B19: $1.99/mo | C19: Plus: 12 highlight colors, 3 mark styles, scoped notes, color-meaning dictionary
A20: Library tier | B20: $4.99/mo | C20: Plus: short-form commentary every chapter, BDB/Thayer's/Vine's, interlinear, nikkudot, recommendations engine
A21: Power tier | B21: $9.99/mo | C21: Plus: Deeper Dive on every chapter, Yoshi's pre-loaded keys, chronological order toggle
A23: CHURN AND CONVERSION
A24: Monthly churn rate | B24: 0.08 | C24: Industry-typical for low-price faith content; real data after 3-6 months will replace
A25: Free-signup → paid-conversion rate | B25: 0.02 | C25: Industry-typical for niche faith software (1–5% range)
A27: ACQUISITION SPEND PER SCENARIO ($/month — paid ads + content + tools)
A28: Current monthly spend (today) | B28: 250 | C28: Midpoint of $1–500 range Yoshi confirmed
A29: Conservative — sustain current spend through year | B29: 250
A30: Base — modest scale-up post-launch (3x by month 6) | B30: 750
A31: Aspirational — meaningful scale-up post-launch (10x by month 6) | B31: 2500
A33: NEW PAID PARTNERS PER $100 ACQUISITION SPEND
A34: Conservative — organic-heavy, modest paid lift | B34: 2 | C34: ≈$50 CAC; ~10 new paid/mo at $500 spend
A35: Base — current organic + paid scaling stays efficient | B35: 3 | C35: ≈$33 CAC; ~22 new paid/mo at $750 spend
A36: Aspirational — efficient channels found + scaled | B36: 4 | C36: ≈$25 CAC; ~100 new paid/mo at $2,500 spend
A38: ORGANIC NEW PAID PARTNERS PER MONTH (independent of paid spend)
A39: Pre-launch (current state, ongoing through W6-W14 sweep) | B39: 3 | C39: Word-of-mouth + YouTube + book-readers stumble in
A40: Post-launch — Conservative | B40: 5
A41: Post-launch — Base | B41: 10
A42: Post-launch — Aspirational | B42: 25 | C42: App Store / Play Store discovery + viral share-with-watermark
A44: FEATURE-PARITY TIMELINE (mapped to remaining wheels W6-W14)
A45: Wheel-shipping pace (wheels per week) | B45: 2 | C45: Yoshi: 'I will have it finished in a month' — ~9 wheels / 4 weeks ≈ 2/wk
A46: Wheels remaining (W6 Search through W14 PDF export) | B46: 9
A47: Wheels to feature-parity milestone (W10 reference library + W11 interlinear) | B47: 5
A48: Weeks to feature parity from today | B48: =B47/B45 -> 2.5
...

Sheet Projection
A1: MONTHLY PROJECTION — 12 months (Jun 2026 → May 2027)
A3: CONSERVATIVE SCENARIO
A4: Month | B4: Date | C4: Acq Spend | D4: New (Paid) | E4: New (Organic) | F4: Churned | G4: Ending Partners | H4: MRR | I4: ARR
A5: 1 | B5: =EDATE(Assumptions!$B$4,1) -> 46196 | C5: =IF(1<=Assumptions!$B$52, Assumptions!$B$28, MIN(Assumptions!$B$28+(1-Assumptions!$B$52)/3*(Assumptions!$B$29-Assumptions!$B$28), Assumptions!$B$29)) -> 250 | D5: =C5/100*Assumptions!$B$34 -> 5 | E5: =IF(1<=Assumptions!$B$52, Assumptions!$B$39, Assumptions!$B$40) -> 3 | F5: =ROUND(Assumptions!$B$5*Assumptions!$B$24,0) -> 1 | G5: =Assumptions!$B$5+D5+E5-F5 -> 20 | H5: =IF(G5=0,0,(Assumptions!$B$5*Assumptions!$B$6+(G5-Assumptions!$B$5)*Assumptions!$B$15)/G5*G5) -> 98.88 | I5: =H5*12 -> 1186.56
A6: 2 | B6: =EDATE(Assumptions!$B$4,2) -> 46226 | C6: =IF(2<=Assumptions!$B$52, Assumptions!$B$28, MIN(Assumptions!$B$28+(2-Assumptions!$B$52)/3*(Assumptions!$B$29-Assumptions!$B$28), Assumptions!$B$29)) -> 250 | D6: =C6/100*Assumptions!$B$34 -> 5 | E6: =IF(2<=Assumptions!$B$52, Assumptions!$B$39, Assumptions!$B$40) -> 3 | F6: =ROUND(G5*Assumptions!$B$24,0) -> 2 | G6: =G5+D6+E6-F6 -> 26 | H6: =IF(G6=0,0,(Assumptions!$B$5*Assumptions!$B$6+(G6-Assumptions!$B$5)*Assumptions!$B$15)/G6*G6) -> 127.92 | I6: =H6*12 -> 1535.04
A7: 3 | B7: =EDATE(Assumptions!$B$4,3) -> 46257 | C7: =IF(3<=Assumptions!$B$52, Assumptions!$B$28, MIN(Assumptions!$B$28+(3-Assumptions!$B$52)/3*(Assumptions!$B$29-Assumptions!$B$28), Assumptions!$B$29)) -> 250 | D7: =C7/100*Assumptions!$B$34 -> 5 | E7: =IF(3<=Assumptions!$B$52, Assumptions!$B$39, Assumptions!$B$40) -> 5 | F7: =ROUND(G6*Assumptions!$B$24,0) -> 2 | G7: =G6+D7+E7-F7 -> 34 | H7: =IF(G7=0,0,(Assumptions!$B$5*Assumptions!$B$6+(G7-Assumptions!$B$5)*Assumptions!$B$15)/G7*G7) -> 166.64 | I7: =H7*12 -> 1999.68
A8: 4 | B8: =EDATE(Assumptions!$B$4,4) -> 46288 | C8: =IF(4<=Assumptions!$B$52, Assumptions!$B$28, MIN(Assumptions!$B$28+(4-Assumptions!$B$52)/3*(Assumptions!$B$29-Assumptions!$B$28), Assumptions!$B$29)) -> 250 | D8: =C8/100*Assumptions!$B$34 -> 5 | E8: =IF(4<=Assumptions!$B$52, Assumptions!$B$39, Assumptions!$B$40) -> 5 | F8: =ROUND(G7*Assumptions!$B$24,0) -> 3 | G8: =G7+D8+E8-F8 -> 41 | H8: =IF(G8=0,0,(Assumptions!$B$5*Assumptions!$B$6+(G8-Assumptions!$B$5)*Assumptions!$B$15)/G8*G8) -> 200.52 | I8: =H8*12 -> 2406.24
A9: 5 | B9: =EDATE(Assumptions!$B$4,5) -> 46318 | C9: =IF(5<=Assumptions!$B$52, Assumptions!$B$28, MIN(Assumptions!$B$28+(5-Assumptions!$B$52)/3*(Assumptions!$B$29-Assumptions!$B$28), Assumptions!$B$29)) -> 250 | D9: =C9/100*Assumptions!$B$34 -> 5 | E9: =IF(5<=Assumptions!$B$52, Assumptions!$B$39, Assumptions!$B$40) -> 5 | F9: =ROUND(G8*Assumptions!$B$24,0) -> 3 | G9: =G8+D9+E9-F9 -> 48 | H9: =IF(G9=0,0,(Assumptions!$B$5*Assumptions!$B$6+(G9-Assumptions!$B$5)*Assumptions!$B$15)/G9*G9) -> 234.4 | I9: =H9*12 -> 2812.8
A10: 6 | B10: =EDATE(Assumptions!$B$4,6) -> 46349 | C10: =IF(6<=Assumptions!$B$52, Assumptions!$B$28, MIN(Assumptions!$B$28+(6-Assumptions!$B$52)/3*(Assumptions!$B$29-Assumptions!$B$28), Assumptions!$B$29)) -> 250 | D10: =C10/100*Assumptions!$B$34 -> 5 | E10: =IF(6<=Assumptions!$B$52, Assumptions!$B$39, Assumptions!$B$40) -> 5 | F10: =ROUND(G9*Assumptions!$B$24,0) -> 4 | G10: =G9+D10+E10-F10 -> 54 | H10: =IF(G10=0,0,(Assumptions!$B$5*Assumptions!$B$6+(G10-Assumptions!$B$5)*Assumptions!$B$15)/G10*G10) -> 263.44 | I10: =H10*12 -> 3161.28
A11: 7 | B11: =EDATE(Assumptions!$B$4,7) -> 46379 | C11: =IF(7<=Assumptions!$B$52, Assumptions!$B$28, MIN(Assumptions!$B$28+(7-Assumptions!$B$52)/3*(Assumptions!$B$29-Assumptions!$B$28), Assumptions!$B$29)) -> 250 | D11: =C11/100*Assumptions!$B$34 -> 5 | E11: =IF(7<=Assumptions!$B$52, Assumptions!$B$39, Assumptions!$B$40) -> 5 | F11: =ROUND(G10*Assumptions!$B$24,0) -> 4 | G11: =G10+D11+E11-F11 -> 60 | H11: =IF(G11=0,0,(Assumptions!$B$5*Assumptions!$B$6+(G11-Assumptions!$B$5)*Assumptions!$B$15)/G11*G11) -> 292.48 | I11: =H11*12 -> 3509.76
A12: 8 | B12: =EDATE(Assumptions!$B$4,8) -> 46410 | C12: =IF(8<=Assumptions!$B$52, Assumptions!$B$28, MIN(Assumptions!$B$28+(8-Assumptions!$B$52)/3*(Assumptions!$B$29-Assumptions!$B$28), Assumptions!$B$29)) -> 250 | D12: =C12/100*Assumptions!$B$34 -> 5 | E12: =IF(8<=Assumptions!$B$52, Assumptions!$B$39, Assumptions!$B$40) -> 5 | F12: =ROUND(G11*Assumptions!$B$24,0) -> 5 | G12: =G11+D12+E12-F12 -> 65 | H12: =IF(G12=0,0,(Assumptions!$B$5*Assumptions!$B$6+(G12-Assumptions!$B$5)*Assumptions!$B$15)/G12*G12) -> 316.68 | I12: =H12*12 -> 3800.16
A13: 9 | B13: =EDATE(Assumptions!$B$4,9) -> 46441 | C13: =IF(9<=Assumptions!$B$52, Assumptions!$B$28, MIN(Assumptions!$B$28+(9-Assumptions!$B$52)/3*(Assumptions!$B$29-Assumptions!$B$28), Assumptions!$B$29)) -> 250 | D13: =C13/100*Assumptions!$B$34 -> 5 | E13: =IF(9<=Assumptions!$B$52, Assumptions!$B$39, Assumptions!$B$40) -> 5 | F13: =ROUND(G12*Assumptions!$B$24,0) -> 5 | G13: =G12+D13+E13-F13 -> 70 | H13: =IF(G13=0,0,(Assumptions!$B$5*Assumptions!$B$6+(G13-Assumptions!$B$5)*Assumptions!$B$15)/G13*G13) -> 340.88 | I13: =H13*12 -> 4090.56
A14: 10 | B14: =EDATE(Assumptions!$B$4,10) -> 46469 | C14: =IF(10<=Assumptions!$B$52, Assumptions!$B$28, MIN(Assumptions!$B$28+(10-Assumptions!$B$52)/3*(Assumptions!$B$29-Assumptions!$B$28), Assumptions!$B$29)) -> 250 | D14: =C14/100*Assumptions!$B$34 -> 5 | E14: =IF(10<=Assumptions!$B$52, Assumptions!$B$39, Assumptions!$B$40) -> 5 | F14: =ROUND(G13*Assumptions!$B$24,0) -> 6 | G14: =G13+D14+E14-F14 -> 74 | H14: =IF(G14=0,0,(Assumptions!$B$5*Assumptions!$B$6+(G14-Assumptions!$B$5)*Assumptions!$B$15)/G14*G14) -> 360.24 | I14: =H14*12 -> 4322.88
A15: 11 | B15: =EDATE(Assumptions!$B$4,11) -> 46500 | C15: =IF(11<=Assumptions!$B$52, Assumptions!$B$28, MIN(Assumptions!$B$28+(11-Assumptions!$B$52)/3*(Assumptions!$B$29-Assumptions!$B$28), Assumptions!$B$29)) -> 250 | D15: =C15/100*Assumptions!$B$34 -> 5 | E15: =IF(11<=Assumptions!$B$52, Assumptions!$B$39, Assumptions!$B$40) -> 5 | F15: =ROUND(G14*Assumptions!$B$24,0) -> 6 | G15: =G14+D15+E15-F15 -> 78 | H15: =IF(G15=0,0,(Assumptions!$B$5*Assumptions!$B$6+(G15-Assumptions!$B$5)*Assumptions!$B$15)/G15*G15) -> 379.6 | I15: =H15*12 -> 4555.2
A16: 12 | B16: =EDATE(Assumptions!$B$4,12) -> 46530 | C16: =IF(12<=Assumptions!$B$52, Assumptions!$B$28, MIN(Assumptions!$B$28+(12-Assumptions!$B$52)/3*(Assumptions!$B$29-Assumptions!$B$28), Assumptions!$B$29)) -> 250 | D16: =C16/100*Assumptions!$B$34 -> 5 | E16: =IF(12<=Assumptions!$B$52, Assumptions!$B$39, Assumptions!$B$40) -> 5 | F16: =ROUND(G15*Assumptions!$B$24,0) -> 6 | G16: =G15+D16+E16-F16 -> 82 | H16: =IF(G16=0,0,(Assumptions!$B$5*Assumptions!$B$6+(G16-Assumptions!$B$5)*Assumptions!$B$15)/G16*G16) -> 398.96 | I16: =H16*12 -> 4787.52
A19: BASE SCENARIO
A20: Month | B20: Date | C20: Acq Spend | D20: New (Paid) | E20: New (Organic) | F20: Churned | G20: Ending Partners | H20: MRR | I20: ARR
A21: 1 | B21: =EDATE(Assumptions!$B$4,1) -> 46196 | C21: =IF(1<=Assumptions!$B$52, Assumptions!$B$28, MIN(Assumptions!$B$28+(1-Assumptions!$B$52)/3*(Assumptions!$B$30-Assumptions!$B$28), Assumptions!$B$30)) -> 250 | D21: =C21/100*Assumptions!$B$35 -> 7.5 | E21: =IF(1<=Assumptions!$B$52, Assumptions!$B$39, Assumptions!$B$41) -> 3 | F21: =ROUND(Assumptions!$B$5*Assumptions!$B$24,0) -> 1 | G21: =Assumptions!$B$5+D21+E21-F21 -> 22.5 | H21: =IF(G21=0,0,(Assumptions!$B$5*Assumptions!$B$6+(G21-Assumptions!$B$5)*Assumptions!$B$15)/G21*G21) -> 110.98 | I21: =H21*12 -> 1331.76
A22: 2 | B22: =EDATE(Assumptions!$B$4,2) -> 46226 | C22: =IF(2<=Assumptions!$B$52, Assumptions!$B$28, MIN(Assumptions!$B$28+(2-Assumptions!$B$52)/3*(Assumptions!$B$30-Assumptions!$B$28), Assumptions!$B$30)) -> 250 | D22: =C22/100*Assumptions!$B$35 -> 7.5 | E22: =IF(2<=Assumptions!$B$52, Assumptions!$B$39, Assumptions!$B$41) -> 3 | F22: =ROUND(G21*Assumptions!$B$24,0) -> 2 | G22: =G21+D22+E22-F22 -> 31 | H22: =IF(G22=0,0,(Assumptions!$B$5*Assumptions!$B$6+(G22-Assumptions!$B$5)*Assumptions!$B$15)/G22*G22) -> 152.12 | I22: =H22*12 -> 1825.44
A23: 3 | B23: =EDATE(Assumptions!$B$4,3) -> 46257 | C23: =IF(3<=Assumptions!$B$52, Assumptions!$B$28, MIN(Assumptions!$B$28+(3-Assumptions!$B$52)/3*(Assumptions!$B$30-Assumptions!$B$28), Assumptions!$B$30)) -> 416.66667 | D23: =C23/100*Assumptions!$B$35 -> 12.5 | E23: =IF(3<=Assumptions!$B$52, Assumptions!$B$39, Assumptions!$B$41) -> 10 | F23: =ROUND(G22*Assumptions!$B$24,0) -> 2 | G23: =G22+D23+E23-F23 -> 51.5 | H23: =IF(G23=0,0,(Assumptions!$B$5*Assumptions!$B$6+(G23-Assumptions!$B$5)*Assumptions!$B$15)/G23*G23) -> 251.34 | I23: =H23*12 -> 3016.08
A24: 4 | B24: =EDATE(Assumptions!$B$4,4) -> 46288 | C24: =IF(4<=Assumptions!$B$52, Assumptions!$B$28, MIN(Assumptions!$B$28+(4-Assumptions!$B$52)/3*(Assumptions!$B$30-Assumptions!$B$28), Assumptions!$B$30)) -> 583.33333 | D24: =C24/100*Assumptions!$B$35 -> 17.5 | E24: =IF(4<=Assumptions!$B$52, Assumptions!$B$39, Assumptions!$B$41) -> 10 | F24: =ROUND(G23*Assumptions!$B$24,0) -> 4 | G24: =G23+D24+E24-F24 -> 75 | H24: =IF(G24=0,0,(Assumptions!$B$5*Assumptions!$B$6+(G24-Assumptions!$B$5)*Assumptions!$B$15)/G24*G24) -> 365.08 | I24: =H24*12 -> 4380.96
A25: 5 | B25: =EDATE(Assumptions!$B$4,5) -> 46318 | C25: =IF(5<=Assumptions!$B$52, Assumptions!$B$28, MIN(Assumptions!$B$28+(5-Assumptions!$B$52)/3*(Assumptions!$B$30-Assumptions!$B$28), Assumptions!$B$30)) -> 750 | D25: =C25/100*Assumptions!$B$35 -> 22.5 | E25: =IF(5<=Assumptions!$B$52, Assumptions!$B$39, Assumptions!$B$41) -> 10 | F25: =ROUND(G24*Assumptions!$B$24,0) -> 6 | G25: =G24+D25+E25-F25 -> 101.5 | H25: =IF(G25=0,0,(Assumptions!$B$5*Assumptions!$B$6+(G25-Assumptions!$B$5)*Assumptions!$B$15)/G25*G25) -> 493.34 | I25: =H25*12 -> 5920.08
A26: 6 | B26: =EDATE(Assumptions!$B$4,6) -> 46349 | C26: =IF(6<=Assumptions!$B$52, Assumptions!$B$28, MIN(Assumptions!$B$28+(6-Assumptions!$B$52)/3*(Assumptions!$B$30-Assumptions!$B$28), Assumptions!$B$30)) -> 750 | D26: =C26/100*Assumptions!$B$35 -> 22.5 | E26: =IF(6<=Assumptions!$B$52, Assumptions!$B$39, Assumptions!$B$41) -> 10 | F26: =ROUND(G25*Assumptions!$B$24,0) -> 8 | G26: =G25+D26+E26-F26 -> 126 | H26: =IF(G26=0,0,(Assumptions!$B$5*Assumptions!$B$6+(G26-Assumptions!$B$5)*Assumptions!$B$15)/G26*G26) -> 611.92 | I26: =H26*12 -> 7343.04
A27: 7 | B27: =EDATE(Assumptions!$B$4,7) -> 46379 | C27: =IF(7<=Assumptions!$B$52, Assumptions!$B$28, MIN(Assumptions!$B$28+(7-Assumptions!$B$52)/3*(Assumptions!$B$30-Assumptions!$B$28), Assumptions!$B$30)) -> 750 | D27: =C27/100*Assumptions!$B$35 -> 22.5 | E27: =IF(7<=Assumptions!$B$52, Assumptions!$B$39, Assumptions!$B$41) -> 10 | F27: =ROUND(G26*Assumptions!$B$24,0) -> 10 | G27: =G26+D27+E27-F27 -> 148.5 | H27: =IF(G27=0,0,(Assumptions!$B$5*Assumptions!$B$6+(G27-Assumptions!$B$5)*Assumptions!$B$15)/G27*G27) -> 720.82 | I27: =H27*12 -> 8649.84
A28: 8 | B28: =EDATE(Assumptions!$B$4,8) -> 46410 | C28: =IF(8<=Assumptions!$B$52, Assumptions!$B$28, MIN(Assumptions!$B$28+(8-Assumptions!$B$52)/3*(Assumptions!$B$30-Assumptions!$B$28), Assumptions!$B$30)) -> 750 | D28: =C28/100*Assumptions!$B$35 -> 22.5 | E28: =IF(8<=Assumptions!$B$52, Assumptions!$B$39, Assumptions!$B$41) -> 10 | F28: =ROUND(G27*Assumptions!$B$24,0) -> 12 | G28: =G27+D28+E28-F28 -> 169 | H28: =IF(G28=0,0,(Assumptions!$B$5*Assumptions!$B$6+(G28-Assumptions!$B$5)*Assumptions!$B$15)/G28*G28) -> 820.04 | I28: =H28*12 -> 9840.48
A29: 9 | B29: =EDATE(Assumptions!$B$4,9) -> 46441 | C29: =IF(9<=Assumptions!$B$52, Assumptions!$B$28, MIN(Assumptions!$B$28+(9-Assumptions!$B$52)/3*(Assumptions!$B$30-Assumptions!$B$28), Assumptions!$B$30)) -> 750 | D29: =C29/100*Assumptions!$B$35 -> 22.5 | E29: =IF(9<=Assumptions!$B$52, Assumptions!$B$39, Assumptions!$B$41) -> 10 | F29: =ROUND(G28*Assumptions!$B$24,0) -> 14 | G29: =G28+D29+E29-F29 -> 187.5 | H29: =IF(G29=0,0,(Assumptions!$B$5*Assumptions!$B$6+(G29-Assumptions!$B$5)*Assumptions!$B$15)/G29*G29) -> 909.58 | I29: =H29*12 -> 10914.96
A30: 10 | B30: =EDATE(Assumptions!$B$4,10) -> 46469 | C30: =IF(10<=Assumptions!$B$52, Assumptions!$B$28, MIN(Assumptions!$B$28+(10-Assumptions!$B$52)/3*(Assumptions!$B$30-Assumptions!$B$28), Assumptions!$B$30)) -> 750 | D30: =C30/100*Assumptions!$B$35 -> 22.5 | E30: =IF(10<=Assumptions!$B$52, Assumptions!$B$39, Assumptions!$B$41) -> 10 | F30: =ROUND(G29*Assumptions!$B$24,0) -> 15 | G30: =G29+D30+E30-F30 -> 205 | H30: =IF(G30=0,0,(Assumptions!$B$5*Assumptions!$B$6+(G30-Assumptions!$B$5)*Assumptions!$B$15)/G30*G30) -> 994.28 | I30: =H30*12 -> 11931.36
A31: 11 | B31: =EDATE(Assumptions!$B$4,11) -> 46500 | C31: =IF(11<=Assumptions!$B$52, Assumptions!$B$28, MIN(Assumptions!$B$28+(11-Assumptions!$B$52)/3*(Assumptions!$B$30-Assumptions!$B$28), Assumptions!$B$30)) -> 750 | D31: =C31/100*Assumptions!$B$35 -> 22.5 | E31: =IF(11<=Assumptions!$B$52, Assumptions!$B$39, Assumptions!$B$41) -> 10 | F31: =ROUND(G30*Assumptions!$B$24,0) -> 16 | G31: =G30+D31+E31-F31 -> 221.5 | H31: =IF(G31=0,0,(Assumptions!$B$5*Assumptions!$B$6+(G31-Assumptions!$B$5)*Assumptions!$B$15)/G31*G31) -> 1074.14 | I31: =H31*12 -> 12889.68
A32: 12 | B32: =EDATE(Assumptions!$B$4,12) -> 46530 | C32: =IF(12<=Assumptions!$B$52, Assumptions!$B$28, MIN(Assumptions!$B$28+(12-Assumptions!$B$52)/3*(Assumptions!$B$30-Assumptions!$B$28), Assumptions!$B$30)) -> 750 | D32: =C32/100*Assumptions!$B$35 -> 22.5 | E32: =IF(12<=Assumptions!$B$52, Assumptions!$B$39, Assumptions!$B$41) -> 10 | F32: =ROUND(G31*Assumptions!$B$24,0) -> 18 | G32: =G31+D32+E32-F32 -> 236 | H32: =IF(G32=0,0,(Assumptions!$B$5*Assumptions!$B$6+(G32-Assumptions!$B$5)*Assumptions!$B$15)/G32*G32) -> 1144.32 | I32: =H32*12 -> 13731.84
A35: ASPIRATIONAL SCENARIO
A36: Month | B36: Date | C36: Acq Spend | D36: New (Paid) | E36: New (Organic) | F36: Churned | G36: Ending Partners | H36: MRR | I36: ARR
A37: 1 | B37: =EDATE(Assumptions!$B$4,1) -> 46196 | C37: =IF(1<=Assumptions!$B$52, Assumptions!$B$28, MIN(Assumptions!$B$28+(1-Assumptions!$B$52)/3*(Assumptions!$B$31-Assumptions!$B$28), Assumptions!$B$31)) -> 250 | D37: =C37/100*Assumptions!$B$36 -> 10 | E37: =IF(1<=Assumptions!$B$52, Assumptions!$B$39, Assumptions!$B$42) -> 3 | F37: =ROUND(Assumptions!$B$5*Assumptions!$B$24,0) -> 1 | G37: =Assumptions!$B$5+D37+E37-F37 -> 25 | H37: =IF(G37=0,0,(Assumptions!$B$5*Assumptions!$B$6+(G37-Assumptions!$B$5)*Assumptions!$B$15)/G37*G37) -> 123.08 | I37: =H37*12 -> 1476.96
A38: 2 | B38: =EDATE(Assumptions!$B$4,2) -> 46226 | C38: =IF(2<=Assumptions!$B$52, Assumptions!$B$28, MIN(Assumptions!$B$28+(2-Assumptions!$B$52)/3*(Assumptions!$B$31-Assumptions!$B$28), Assumptions!$B$31)) -> 250 | D38: =C38/100*Assumptions!$B$36 -> 10 | E38: =IF(2<=Assumptions!$B$52, Assumptions!$B$39, Assumptions!$B$42) -> 3 | F38: =ROUND(G37*Assumptions!$B$24,0) -> 2 | G38: =G37+D38+E38-F38 -> 36 | H38: =IF(G38=0,0,(Assumptions!$B$5*Assumptions!$B$6+(G38-Assumptions!$B$5)*Assumptions!$B$15)/G38*G38) -> 176.32 | I38: =H38*12 -> 2115.84
A39: 3 | B39: =EDATE(Assumptions!$B$4,3) -> 46257 | C39: =IF(3<=Assumptions!$B$52, Assumptions!$B$28, MIN(Assumptions!$B$28+(3-Assumptions!$B$52)/3*(Assumptions!$B$31-Assumptions!$B$28), Assumptions!$B$31)) -> 1000 | D39: =C39/100*Assumptions!$B$36 -> 40 | E39: =IF(3<=Assumptions!$B$52, Assumptions!$B$39, Assumptions!$B$42) -> 25 | F39: =ROUND(G38*Assumptions!$B$24,0) -> 3 | G39: =G38+D39+E39-F39 -> 98 | H39: =IF(G39=0,0,(Assumptions!$B$5*Assumptions!$B$6+(G39-Assumptions!$B$5)*Assumptions!$B$15)/G39*G39) -> 476.4 | I39: =H39*12 -> 5716.8
A40: 4 | B40: =EDATE(Assumptions!$B$4,4) -> 46288 | C40: =IF(4<=Assumptions!$B$52, Assumptions!$B$28, MIN(Assumptions!$B$28+(4-Assumptions!$B$52)/3*(Assumptions!$B$31-Assumptions!$B$28), Assumptions!$B$31)) -> 1750 | D40: =C40/100*Assumptions!$B$36 -> 70 | E40: =IF(4<=Assumptions!$B$52, Assumptions!$B$39, Assumptions!$B$42) -> 25 | F40: =ROUND(G39*Assumptions!$B$24,0) -> 8 | G40: =G39+D40+E40-F40 -> 185 | H40: =IF(G40=0,0,(Assumptions!$B$5*Assumptions!$B$6+(G40-Assumptions!$B$5)*Assumptions!$B$15)/G40*G40) -> 897.48 | I40: =H40*12 -> 10769.76
A41: 5 | B41: =EDATE(Assumptions!$B$4,5) -> 46318 | C41: =IF(5<=Assumptions!$B$52, Assumptions!$B$28, MIN(Assumptions!$B$28+(5-Assumptions!$B$52)/3*(Assumptions!$B$31-Assumptions!$B$28), Assumptions!$B$31)) -> 2500 | D41: =C41/100*Assumptions!$B$36 -> 100 | E41: =IF(5<=Assumptions!$B$52, Assumptions!$B$39, Assumptions!$B$42) -> 25 | F41: =ROUND(G40*Assumptions!$B$24,0) -> 15 | G41: =G40+D41+E41-F41 -> 295 | H41: =IF(G41=0,0,(Assumptions!$B$5*Assumptions!$B$6+(G41-Assumptions!$B$5)*Assumptions!$B$15)/G41*G41) -> 1429.88 | I41: =H41*12 -> 17158.56
A42: 6 | B42: =EDATE(Assumptions!$B$4,6) -> 46349 | C42: =IF(6<=Assumptions!$B$52, Assumptions!$B$28, MIN(Assumptions!$B$28+(6-Assumptions!$B$52)/3*(Assumptions!$B$31-Assumptions!$B$28), Assumptions!$B$31)) -> 2500 | D42: =C42/100*Assumptions!$B$36 -> 100 | E42: =IF(6<=Assumptions!$B$52, Assumptions!$B$39, Assumptions!$B$42) -> 25 | F42: =ROUND(G41*Assumptions!$B$24,0) -> 24 | G42: =G41+D42+E42-F42 -> 396 | H42: =IF(G42=0,0,(Assumptions!$B$5*Assumptions!$B$6+(G42-Assumptions!$B$5)*Assumptions!$B$15)/G42*G42) -> 1918.72 | I42: =H42*12 -> 23024.64
A43: 7 | B43: =EDATE(Assumptions!$B$4,7) -> 46379 | C43: =IF(7<=Assumptions!$B$52, Assumptions!$B$28, MIN(Assumptions!$B$28+(7-Assumptions!$B$52)/3*(Assumptions!$B$31-Assumptions!$B$28), Assumptions!$B$31)) -> 2500 | D43: =C43/100*Assumptions!$B$36 -> 100 | E43: =IF(7<=Assumptions!$B$52, Assumptions!$B$39, Assumptions!$B$42) -> 25 | F43: =ROUND(G42*Assumptions!$B$24,0) -> 32 | G43: =G42+D43+E43-F43 -> 489 | H43: =IF(G43=0,0,(Assumptions!$B$5*Assumptions!$B$6+(G43-Assumptions!$B$5)*Assumptions!$B$15)/G43*G43) -> 2368.84 | I43: =H43*12 -> 28426.08
A44: 8 | B44: =EDATE(Assumptions!$B$4,8) -> 46410 | C44: =IF(8<=Assumptions!$B$52, Assumptions!$B$28, MIN(Assumptions!$B$28+(8-Assumptions!$B$52)/3*(Assumptions!$B$31-Assumptions!$B$28), Assumptions!$B$31)) -> 2500 | D44: =C44/100*Assumptions!$B$36 -> 100 | E44: =IF(8<=Assumptions!$B$52, Assumptions!$B$39, Assumptions!$B$42) -> 25 | F44: =ROUND(G43*Assumptions!$B$24,0) -> 39 | G44: =G43+D44+E44-F44 -> 575 | H44: =IF(G44=0,0,(Assumptions!$B$5*Assumptions!$B$6+(G44-Assumptions!$B$5)*Assumptions!$B$15)/G44*G44) -> 2785.08 | I44: =H44*12 -> 33420.96
A45: 9 | B45: =EDATE(Assumptions!$B$4,9) -> 46441 | C45: =IF(9<=Assumptions!$B$52, Assumptions!$B$28, MIN(Assumptions!$B$28+(9-Assumptions!$B$52)/3*(Assumptions!$B$31-Assumptions!$B$28), Assumptions!$B$31)) -> 2500 | D45: =C45/100*Assumptions!$B$36 -> 100 | E45: =IF(9<=Assumptions!$B$52, Assumptions!$B$39, Assumptions!$B$42) -> 25 | F45: =ROUND(G44*Assumptions!$B$24,0) -> 46 | G45: =G44+D45+E45-F45 -> 654 | H45: =IF(G45=0,0,(Assumptions!$B$5*Assumptions!$B$6+(G45-Assumptions!$B$5)*Assumptions!$B$15)/G45*G45) -> 3167.44 | I45: =H45*12 -> 38009.28
...

Sheet Logos Comparison
A1: LOGOS COMPARISON — pricing + feature-parity scorecard
A3: MONTHLY SUBSCRIPTION PRICING — head-to-head
A4: Tier role | B4: ROP Study Bible | C4: Logos equivalent | D4: ROP $/mo | E4: Logos $/mo | F4: ROP discount vs Logos
A5: Entry / free tier | B5: Free | C5: (no equivalent) | D5: 0 | E5: 0 | F5: n/a
A6: Personal study | B6: Notes ($1.99) | C6: (no direct comp) | D6: 1.99 | E6: 0 | F6: n/a
A7: Serious study | B7: Library ($4.99) | C7: Premium ($9.99) | D7: 4.99 | E7: 9.99 | F7: =1-D7/E7 -> 0.5005005
A8: Sermon/pastor prep | B8: Library ($4.99) | C8: Pro ($14.99) | D8: 4.99 | E8: 14.99 | F8: =1-D8/E8 -> 0.66711141
A9: Academic / power-user | B9: Power ($9.99) | C9: Max ($19.99) | D9: 9.99 | E9: 19.99 | F9: =1-D9/E9 -> 0.50025013
A11: Logos pricing source: logos.com/configure/subscriptions (verified May 2026)
A13: FEATURE PARITY SCORECARD
A14: Feature surface | B14: ROP — current state | C14: ROP — when shipped | D14: Logos has it? | E14: Logos tier required | F14: Where ROP exceeds Logos
A15: Restored sacred names (Yahuah, Yahusha, etc. with English parentheticals) | B15: LIVE — Free tier | C15: Already live | D15: No | E15: (unavailable) | F15: Unique to ROP — third-commandment fidelity
A16: Apocrypha + pseudepigrapha library at Free tier (1 Enoch, Jubilees, Jasher, Charles Vol 1+2, Josephus, Sonnini) | B16: LIVE — Free tier | C16: Already live | D16: Partial — paid only | E16: Add-on libraries (extra cost) | F16: Free at ROP; paid at Logos
A17: Strong's reference lookup (tap any word) | B17: LIVE — Free tier | C17: Already live (S120-S121) | D17: Yes | E17: All tiers | F17: Free at ROP
A18: 13-color highlighting + 3 mark styles | B18: LIVE — $1.99 tier | C18: Already live (S113, S117) | D18: Yes | E18: All tiers | F18: $1.99 vs $9.99+
A19: Notes (single + per-verse + global notepad) | B19: LIVE — Free / $1.99 tiers | C19: S124 (Free V1); $1.99 hub W8 | D19: Yes | E19: All tiers | F19: Free V1; $1.99 hub
A20: Bookmarks (color-tinted with tags) | B20: LIVE — Free tier | C20: Already live (S124) | D20: Yes | E20: All tiers | F20: Free at ROP
A21: Full-text search across canon + extras | B21: Server live; UI in W6 | C21: W6 — this session | D21: Yes | E21: All tiers | F21: Free at ROP
A22: Reading position persistence | B22: LIVE — Free tier | C22: Already live (S116) | D22: Yes | E22: All tiers | F22: Free at ROP
A23: Chapter swipe + arrow navigation | B23: LIVE | C23: Already live (S121 W2) | D23: Yes (basic) | E23: All tiers | F23: Tied
A24: Cross-references with full restored library (bidirectional, curated) | B24: Two threads free; full apparatus $4.99 | C24: S110-S112 (Matthew); ongoing for other books | D24: Yes | E24: Premium+ | F24: Curated AI-free; full restored library
A25: Commentary on every chapter (short-form, framework-bearing) | B25: Matthew done; rolling out | C25: $4.99 tier; on-going chapter rollout | D25: Yes (3rd-party commentaries) | E25: Pro+ | F25: Original framework reading; not 3rd-party
... A35: Sermon-prep workflow tools (outline templates, slide export) | B35: Not in roadmap | C35: Not planned | D35: Yes (key Pro audience) | E35: Pro | F35: Gap — Logos serves a market segment ROP does not target
A38: WHERE ROP EXCEEDS LOGOS (the framework-reading moat)
A39: • Restored sacred names with parenthetical equivalents — third-commandment fidelity Logos does not offer.
A40: • Apocrypha + pseudepigrapha (1 Enoch, Jubilees, Jasher, full Charles Vol 1 + 2) at the FREE tier — Logos charges separately for these.
A41: • Original framework theological commentary in Yoshi's voice — not third-party reprints. Reads the canon plainly through the framework that institutional Christianity, Judaism, Hebrew Roots, and Islam all flinch from.
A42: • 100% human-curated cross-references and recommendations — no AI inference at runtime, no AI-generated similarity. The data is the framework, made traceable.
A43: • Roughly half the price across every comparable tier — Library $4.99 vs Logos Pro $14.99; Power $9.99 vs Logos Max $19.99.
A44: • Full apocrypha and pseudepigrapha at no extra charge — the canon as it stood before the Reformation's truncation.
A45: • Nikkudot-strip surfaces the Masoretic interpretive layer that no other major Bible app exposes.
A48: GAPS — where Logos still has more (post-launch roadmap)
A49: • Atlases + maps — planned post-launch; not in the current 14-wheel sweep.
A50: • Sermon-prep workflow tools (outline templates, slide export) — not in roadmap. Targets a different market segment.
A51: • Original-language morphological tagging depth — Logos has decades of academic alignment work; ROP ships Strong's-level alignment today, with interlinear at W11.
... A53: • Logos has 750k+ active monthly users (Faithlife is privately held; estimates only). ROP starts from low double-digit paid partners — the brand-trust gap is real and the model accounts for it in the Conservative scenario.

Sheet Milestones
A1: MILESTONES — checkpoints + unit economics
A3: PROJECTION CHECKPOINTS
A4: Horizon | B4: Calendar date | C4: Scenario | D4: Ending paying partners | E4: MRR ($) | F4: ARR ($)
A5: 3 months | B5: =EDATE(Assumptions!$B$4,3) -> 46257 | C5: Conservative | D5: =Projection!G7 -> 34 | E5: =Projection!H7 -> 166.64 | F5: =Projection!I7 -> 1999.68
A6: 3 months | B6: =EDATE(Assumptions!$B$4,3) -> 46257 | C6: Base | D6: =Projection!G23 -> 51.5 | E6: =Projection!H23 -> 251.34 | F6: =Projection!I23 -> 3016.08
A7: 3 months | B7: =EDATE(Assumptions!$B$4,3) -> 46257 | C7: Aspirational | D7: =Projection!G39 -> 98 | E7: =Projection!H39 -> 476.4 | F7: =Projection!I39 -> 5716.8
A9: 6 months | B9: =EDATE(Assumptions!$B$4,6) -> 46349 | C9: Conservative | D9: =Projection!G10 -> 54 | E9: =Projection!H10 -> 263.44 | F9: =Projection!I10 -> 3161.28
A10: 6 months | B10: =EDATE(Assumptions!$B$4,6) -> 46349 | C10: Base | D10: =Projection!G26 -> 126 | E10: =Projection!H26 -> 611.92 | F10: =Projection!I26 -> 7343.04
A11: 6 months | B11: =EDATE(Assumptions!$B$4,6) -> 46349 | C11: Aspirational | D11: =Projection!G42 -> 396 | E11: =Projection!H42 -> 1918.72 | F11: =Projection!I42 -> 23024.64
A13: 12 months | B13: =EDATE(Assumptions!$B$4,12) -> 46530 | C13: Conservative | D13: =Projection!G16 -> 82 | E13: =Projection!H16 -> 398.96 | F13: =Projection!I16 -> 4787.52
A14: 12 months | B14: =EDATE(Assumptions!$B$4,12) -> 46530 | C14: Base | D14: =Projection!G32 -> 236 | E14: =Projection!H32 -> 1144.32 | F14: =Projection!I32 -> 13731.84
A15: 12 months | B15: =EDATE(Assumptions!$B$4,12) -> 46530 | C15: Aspirational | D15: =Projection!G48 -> 855 | E15: =Projection!H48 -> 4140.28 | F15: =Projection!I48 -> 49683.36
A18: LOGOS FEATURE-PARITY MILESTONE
A19: Feature-parity date (W10 reference library + W11 interlinear shipped) | D19: =Assumptions!B49 -> 46182.5
A20: Full launch date (all 14 wheels + Google Play / App Store listings live) | D20: =Assumptions!B51 -> 46210.5
A21: Weeks from today to feature parity | D21: =Assumptions!B48 -> 2.5
A22: Weeks from today to full launch | D22: =Assumptions!B50 -> 6.5
A25: UNIT ECONOMICS
A26: Metric | B26: Conservative | C26: Base | D26: Aspirational | E26: Healthy benchmark | F26: Notes
A27: ARPU — blended price per new paid partner ($/mo) | B27: =Assumptions!B15 -> 4.84 | C27: =Assumptions!B15 -> 4.84 | D27: =Assumptions!B15 -> 4.84 | E27: n/a | F27: Same blended price assumption across scenarios (tier mix is scenario-independent)
A28: LTV — lifetime value per partner ($) | B28: =B27/Assumptions!B24 -> 60.5 | C28: =C27/Assumptions!B24 -> 60.5 | D28: =D27/Assumptions!B24 -> 60.5 | E28: n/a | F28: LTV = ARPU / monthly churn (simple geometric series)
A29: CAC — customer acquisition cost ($/paid partner) | B29: =Assumptions!B29/(Assumptions!B29/100*Assumptions!B34) -> 50 | C29: =Assumptions!B30/(Assumptions!B30/100*Assumptions!B35) -> 33.333333 | D29: =Assumptions!B31/(Assumptions!B31/100*Assumptions!B36) -> 25 | E29: < $50 | F29: Paid CAC only; organic partners are 'free' (audience-built)
A30: LTV / CAC ratio | B30: =B28/B29 -> 1.21 | C30: =C28/C29 -> 1.815 | D30: =D28/D29 -> 2.42 | E30: > 3.0 healthy | F30: Above 3.0 = unit economics support scaling spend; below 1 = burn
A31: Mature monthly acquisition spend ($) | B31: =Assumptions!B29 -> 250 | C31: =Assumptions!B30 -> 750 | D31: =Assumptions!B31 -> 2500 | E31: n/a
A34: KEY OBSERVATIONS + RISKS
A35: • Unit economics are MARGINAL, not strong. LTV is ~$60.50 per partner (ARPU $4.84/mo ÷ 8% monthly churn). CAC ranges from $50 (Conservative) to $25 (Aspirational). LTV/CAC ratios: Conservative 1.21x, Base 1.82x, Aspirational 2.42x. The healthy benchmark is 3.0x or higher. The current model says: paid acquisition pays back, but the cushion is thin.
A36: • Three levers move LTV/CAC into healthy territory. (a) Lower churn from 8% to 5% → LTV jumps to $97/partner → Base LTV/CAC = 2.9x. (b) Shift tier mix from $4.99-dominant to $9.99-dominant → ARPU rises from $4.84 to $7+/mo. (c) Improve paid efficiency past 4 paid partners per $100 spend → Aspirational case clears 3.0x. Real data after 3-6 months of meaningful acquisition will tell which lever is realistic.
A37: • Feature parity with Logos's core toolset (lexicons at W10 + interlinear at W11) lands by mid-June 2026 if Yoshi holds the 2-wheels-per-week pace. This is the moment the marketing story shifts from 'restored-names study Bible' to 'restored-names study Bible that does everything Logos's $14.99 Pro tier does at $4.99 — and ships features Logos does not have at any price.'
A38: • The 12-month aspirational scenario lands at ~855 paying partners and ~$50k ARR. That assumes meaningful paid-spend scaling ($2,500/mo by month 6), efficient channels stay efficient, and post-launch organic discovery hits 25 new paid partners/month from app store + viral share-with-watermark. The model is most fragile here — paid efficiency commonly degrades with scale.
A39: • Logos has 750k+ active monthly users (estimate; Faithlife is privately held). Even the aspirational 12-month projection lands at <0.2% of Logos's monthly active count. The total addressable market is enormous; the strategy is not to take Logos's share but to find the slice of that 750k who specifically want the framework reading — restored sacred names, full apocrypha/pseudepigrapha, no antichrist Paul-reading, half the price.
A40: • Material model gaps to flag: (a) free-signup pool sizing is not modeled — new-paid is treated as a function of spend + organic, skipping the free-tier reservoir that should compound; (b) tier mix is scenario-independent, but the real mix may shift with marketing message (a 'pastor-targeting' push could move the mix toward $4.99 Library; a 'serious-student' push toward $9.99 Power); (c) annual-billing discounts are not modeled — Logos gives ~2 months free on annual; if ROP follows suit, ARPU drops ~17% for annual subscribers but churn drops materially too.
